Traceback (most recent call last):
  File "<frozen importlib._bootstrap_external>", line 148, in _path_is_mode_type
  File "<frozen importlib._bootstrap_external>", line 142, in _path_stat
FileNotFoundError: [Errno 2] No such file or directory: '/usr/lib/python3.8/urllib/__init__.so'

During handling of the above exception, another exception occurred:

Traceback (most recent call last):
  File "setup.py", line 1, in <module>
    from setuptools import setup
  File "/usr/lib/python3/dist-packages/setuptools/__init__.py", line 17, in <module>
    import setuptools.version
  File "/usr/lib/python3/dist-packages/setuptools/version.py", line 1, in <module>
    import pkg_resources
  File "/usr/lib/python3/dist-packages/pkg_resources/__init__.py", line 36, in <module>
    import email.parser
  File "/usr/lib/python3.8/email/parser.py", line 12, in <module>
    from email.feedparser import FeedParser, BytesFeedParser
  File "/usr/lib/python3.8/email/feedparser.py", line 27, in <module>
    from email._policybase import compat32
  File "/usr/lib/python3.8/email/_policybase.py", line 9, in <module>
    from email.utils import _has_surrogates
  File "/usr/lib/python3.8/email/utils.py", line 31, in <module>
    import urllib.parse
  File "<frozen importlib._bootstrap>", line 991, in _find_and_load
  File "<frozen importlib._bootstrap>", line 971, in _find_and_load_unlocked
  File "<frozen importlib._bootstrap>", line 914, in _find_spec
  File "<frozen importlib._bootstrap_external>", line 1407, in find_spec
  File "<frozen importlib._bootstrap_external>", line 1379, in _get_spec
  File "<frozen importlib._bootstrap_external>", line 1525, in find_spec
  File "<frozen importlib._bootstrap_external>", line 156, in _path_isfile
  File "<frozen importlib._bootstrap_external>", line 148, in _path_is_mode_type
KeyboardInterrupt
